2024-09-25 11:12:52,586 - app_logger - DEBUG - This is a debug message
2024-09-25 11:12:52,586 - app_logger - INFO - This is an info message
2024-09-25 11:12:52,586 - app_logger - WARNING - This is a warning message
2024-09-25 11:12:52,586 - app_logger - ERROR - This is an error message
2024-09-25 11:23:43,347 - app_logger - INFO - Received login request for user: poc3
2024-09-25 11:24:14,350 - app_logger - INFO - Received login request for user: poc2
2024-09-25 11:38:53,501 - app_logger - DEBUG - Received signup request for user: testuser
2024-09-25 11:38:53,501 - app_logger - INFO - Attempting to create user: testuser
2024-09-25 11:38:53,794 - app_logger - ERROR - 發生錯誤: 'user_role' is an invalid keyword argument for UserSignup
2024-09-25 11:38:53,794 - app_logger - ERROR - AuthController error for user testuser: 發生錯誤: 'user_role' is an invalid keyword argument for UserSignup
2024-09-25 11:41:56,299 - app_logger - DEBUG - Received signup request for user: testuser
2024-09-25 11:41:56,300 - app_logger - INFO - Attempting to create user: testuser
2024-09-25 11:41:56,998 - app_logger - INFO - User testuser created successfully
2024-09-25 11:50:13,022 - app_logger - DEBUG - Received signup request for user: testuser
2024-09-25 11:50:13,023 - app_logger - INFO - Attempting to create user: testuser
2024-09-25 11:50:13,588 - app_logger - ERROR - 發生錯誤: (pymysql.err.IntegrityError) (1062, "Duplicate entry 'testuser' for key 'user_signup.username'")
[SQL: INSERT INTO user_signup (username, password, email, company_name, license_amount, disabled, create_date, update_date) VALUES (%(username)s, %(password)s, %(email)s, %(company_name)s, %(license_amount)s, %(disabled)s, %(create_date)s, %(update_date)s)]
[parameters: {'username': 'testuser', 'password': '$2b$12$My1oauSzIkPxBL5r/r/cse932OrUQFTAw8Zmib24KTZ8pnx3pC/v2', 'email': 'testuser@example.com', 'company_name': 'Test Company', 'license_amount': None, 'disabled': 0, 'create_date': datetime.datetime(2024, 9, 25, 11, 50, 13, 294671), 'update_date': datetime.datetime(2024, 9, 25, 11, 50, 13, 294698)}]
(Background on this error at: https://sqlalche.me/e/20/gkpj)
2024-09-25 11:50:13,589 - app_logger - ERROR - AuthController error for user testuser: 發生錯誤: (pymysql.err.IntegrityError) (1062, "Duplicate entry 'testuser' for key 'user_signup.username'")
[SQL: INSERT INTO user_signup (username, password, email, company_name, license_amount, disabled, create_date, update_date) VALUES (%(username)s, %(password)s, %(email)s, %(company_name)s, %(license_amount)s, %(disabled)s, %(create_date)s, %(update_date)s)]
[parameters: {'username': 'testuser', 'password': '$2b$12$My1oauSzIkPxBL5r/r/cse932OrUQFTAw8Zmib24KTZ8pnx3pC/v2', 'email': 'testuser@example.com', 'company_name': 'Test Company', 'license_amount': None, 'disabled': 0, 'create_date': datetime.datetime(2024, 9, 25, 11, 50, 13, 294671), 'update_date': datetime.datetime(2024, 9, 25, 11, 50, 13, 294698)}]
(Background on this error at: https://sqlalche.me/e/20/gkpj)
2024-09-25 11:54:12,941 - app_logger - DEBUG - Received signup request for user: testuser
2024-09-25 11:54:12,941 - app_logger - INFO - Attempting to create user: testuser
2024-09-25 11:55:06,830 - app_logger - DEBUG - Received signup request for user: testuser2
2024-09-25 11:55:06,831 - app_logger - INFO - Attempting to create user: testuser2
2024-09-25 11:55:07,130 - app_logger - INFO - User testuser2 created successfully
2024-09-25 11:58:44,578 - app_logger - DEBUG - Received signup request for user: testuser2
2024-09-25 11:58:44,578 - app_logger - INFO - Attempting to create user: testuser2
2024-09-25 11:58:48,702 - app_logger - DEBUG - Received signup request for user: testuser3
2024-09-25 11:58:48,702 - app_logger - INFO - Attempting to create user: testuser3
2024-09-25 11:58:49,405 - app_logger - INFO - User testuser3 created successfully
2024-09-25 12:26:00,628 - app_logger - DEBUG - Received signup request for user: testuser4
2024-09-25 12:26:00,629 - app_logger - INFO - Attempting to create user: testuser4
2024-09-25 12:26:01,148 - app_logger - INFO - User testuser4 created successfully
2024-09-25 18:44:20,499 - app_logger - ERROR - type object 'AuthController' has no attribute 'get_group_email_map'
2024-09-25 18:45:28,052 - app_logger - ERROR - Unexpected error in get_group: type object 'AuthController' has no attribute 'get_group_email_map'
2024-09-25 19:03:13,813 - app_logger - ERROR - Unexpected error in get_group: type object 'AuthController' has no attribute 'get_group_email_map'
2024-09-25 19:04:30,869 - app_logger - ERROR - Unexpected error in get_group: 1 validation error for GroupEmailMap
__root__
  Input should be a valid string [type=string_type, input_value={}, input_type=dict]
    For further information visit https://errors.pydantic.dev/2.8/v/string_type
2024-09-25 19:27:03,740 - app_logger - INFO - User 11 permission check for group admin: False
2024-09-25 19:29:18,731 - app_logger - INFO - User 11 permission check for group admin: False
2024-09-25 19:32:18,724 - app_logger - ERROR - Unexpected error in approve_email: type object 'UserSignup' has no attribute 'update_disabled_status'
2024-09-25 19:33:07,935 - app_logger - ERROR - Unexpected error in approve_email: type object 'UserSignup' has no attribute 'update_disabled_status'
2024-09-25 19:34:06,716 - app_logger - ERROR - Unexpected error in approve_email: type object 'UserSignup' has no attribute 'update_disabled_status'
2024-09-25 23:00:11,845 - app_logger - INFO - User 11 permission check for group admin: False
2024-09-27 16:07:52,015 - app_logger - ERROR - Unexpected error in get_group: (pymysql.err.OperationalError) (1054, "Unknown column 'group_signup.user_id' in 'on clause'")
[SQL: SELECT group_signup.group_name AS group_signup_group_name, user_signup.email AS user_signup_email 
FROM group_signup INNER JOIN user_signup ON group_signup.user_id = user_signup.id]
(Background on this error at: https://sqlalche.me/e/20/e3q8)
2024-09-28 10:01:58,345 - app_logger - INFO - User 11 permission check for group admin: False
2024-10-01 13:58:40,725 - app_logger - INFO - Verifying password: 3cop $2b$12$rSE0IbSVlx2Bo2V/ytBQne.UaIbLVG5NlYXA1SXiWQ6uPpWagxno2
2024-10-01 14:00:41,859 - app_logger - INFO - Verifying password: 3cop $2b$12$rSE0IbSVlx2Bo2V/ytBQne.UaIbLVG5NlYXA1SXiWQ6uPpWagxno2
2024-10-01 14:08:28,807 - app_logger - ERROR - User is disabled: poc2
2024-10-01 14:08:30,820 - app_logger - ERROR - User is disabled: poc2
2024-10-01 14:09:56,804 - app_logger - ERROR - Token validation error: Invalid token
2024-10-01 14:10:01,885 - app_logger - ERROR - Token validation error: Invalid token
2024-10-01 14:12:35,780 - app_logger - DEBUG - Password verification result: False
2024-10-01 14:12:36,036 - app_logger - ERROR - Incorrect password for user: poc2
2024-10-01 14:12:54,743 - app_logger - DEBUG - Password verification result: True
2024-10-01 14:24:38,583 - app_logger - INFO - User 66 permission check for group admin: False
2024-10-01 14:24:48,098 - app_logger - INFO - User 66 permission check for group admin: False
